
### can't run pytest because error - chatgpt possibly solutions: 

The error message you're encountering indicates that pytest, when setting up the Django test database, is unable to connect to the PostgreSQL database because it cannot resolve the hostname "db" to an IP address. This is a common issue when running tests in an environment where the database hostname is configured for use with Docker (or another container service) but the tests are being run outside of that environment, causing the hostname to be unresolvable.

Possible Solutions:
* Check your Django settings: Ensure that your DATABASES configuration in Django's settings is using the correct hostname for your development environment. If "db" is specified as the hostname in your settings (which is common in Docker setups), you might need to adjust this for testing purposes or when running tests outside of Docker.

    For local testing, you might need to change the hostname to localhost or 127.0.0.1 if your PostgreSQL database is running locally outside Docker.

* Use environment variables: A more flexible approach is to use environment variables to dynamically set the database hostname and other parameters. This way, you can have different configurations for different environments (development, testing, production, etc.) without changing the code.

    In your settings file, you could have something like this:

```python
DATABASES = {
    'default': {
        'ENGINE': 'django.db.backends.postgresql',
        'NAME': os.environ.get('DB_NAME', 'your_default_db_name'),
        'USER': os.environ.get('DB_USER', 'your_default_user'),
        'PASSWORD': os.environ.get('DB_PASSWORD', 'your_default_password'),
        'HOST': os.environ.get('DB_HOST', 'localhost'),  # Use 'localhost' or '127.0.0.1' for local testing
        'PORT': os.environ.get('DB_PORT', '5432'),
    }
}
```
    Then, you can set these environment variables in your testing environment or before running tests.

* Network Configuration for Docker: If you're actually running your tests within Docker and still encountering this issue, make sure that your testing environment has access to the same network as your database container. This involves configuring Docker network settings properly.

    ##### How do I run tests in Docker? 